File: SampleData/repeated scan_450°C[1249].xrdml
<?xml version="1.0" encoding="UTF-8"?>
<xrdMeasurements xmlns="http://www.xrdml.com/XRDMeasurement/1.5" xmlns:xsi="http://www.w3.org/2001/XMLSchema-instance" xsi:schemaLocation="http://www.xrdml.com/XRDMeasurement/1.5 http://www.xrdml.com/XRDMeasurement/1.5/XRDMeasurement.xsd" status="Completed">
	<comment>
		<entry>Configuration=XRK900 "Ramp", Owner=User-1, Creation date=3/7/2016 4:24:54 PM</entry>
		<entry>Goniometer=Theta/Theta; Minimum step size 2Theta:0.0001; Minimum step size Omega:0.0001</entry>
		<entry>Sample stage=AP XRK-900 with z-axis; Minimum step size Z:0.001</entry>
		<entry>Diffractometer system=EMPYREAN</entry>
		<entry>Measurement program=C:\PANalytical\Data Collector\Programs\Richard\Temp dependent measurement\repeated scan.xrdmp, Identifier={157C593B-B1CD-456E-A58D-79E2E7D3BBF9}</entry>
		<entry>Batch program=C:\PANalytical\Data Collector\Programs\Richard\Temp dependent measurement\non ambient scan.xrdmp, Identifier={7A24D3C2-FCB5-493B-A367-317517E9BF7C}</entry>
	</comment>
	<sample type="To be analyzed">
		<id></id>
		<name></name>
		<preparedBy></preparedBy>
	</sample>
	<xrdMeasurement measurementType="Repeated scan" status="Completed" sampleMode="Reflection">
		<comment>
			<entry/>
		</comment>
		<usedWavelength intended="K-Alpha">
			<kAlpha1 unit="Angstrom">1.5405980</kAlpha1>
			<kAlpha2 unit="Angstrom">1.5444260</kAlpha2>
			<kBeta unit="Angstrom">1.3922500</kBeta>
			<ratioKAlpha2KAlpha1>0.5000</ratioKAlpha2KAlpha1>
		</usedWavelength>
		<incidentBeamPath>
			<radius unit="mm">240.00</radius>
			<xRayTube id="1010041" name="Empyrean Cu LFF (9430 033 7300x) DK303567">
				<tension unit="kV">45</tension>
				<current unit="mA">40</current>
				<anodeMaterial>Cu</anodeMaterial>
				<focus type="Line">
					<length unit="mm">12.0</length>
					<width unit="mm">0.4</width>
					<takeOffAngle unit="deg">6.0</takeOffAngle>
				</focus>
			</xRayTube>
			<sollerSlit id="21010002" name="Soller slits 0.04 rad.">
				<opening unit="rad">0.0400</opening>
			</sollerSlit>
			<mask id="22080002" name="Fixed incident beam mask 10 mm">
				<width unit="mm">6.60</width>
			</mask>
			<antiScatterSlit id="22010004" name="Fixed slit 1/2Â°" xsi:type="fixedAntiScatterSlitType">
				<height unit="mm">0.76</height>
			</antiScatterSlit>
			<divergenceSlit id="22010012" name="Programmable divergence slit" xsi:type="fixedDivergenceSlitType">
				<distanceToSample unit="mm">140.00</distanceToSample>
				<angle unit="deg">0.25</angle>
			</divergenceSlit>
		</incidentBeamPath>
		<sampleOffset>
			<position axis="Omega" unit="deg">0.3514</position>
		</sampleOffset>
		<diffractedBeamPath>
			<radius unit="mm">240.00</radius>
			<antiScatterSlit id="22060009" name="Programmable anti-scatter slit" xsi:type="fixedAntiScatterSlitType">
				<angle unit="deg">0.25</angle>
			</antiScatterSlit>
			<sollerSlit id="21010002" name="Soller slits 0.04 rad.">
				<opening unit="rad">0.0400</opening>
			</sollerSlit>
			<monochromator id="23010033" name="Diffracted beam monochr. for PIXcel and Cu" hybrid="false">
				<crystal type="Symmetric" shape="Flat">C</crystal>
				<numberOfReflections>1</numberOfReflections>
				<hkl>
					<h>0</h>
					<k>0</k>
					<l>2</l>
				</hkl>
			</monochromator>
			<detector id="7010015" name="PIXcel1D detector" xsi:type="rtmsDetectorType">
				<phd>
					<lowerLevel unit="%">25.0</lowerLevel>
					<upperLevel unit="%">100.0</upperLevel>
				</phd>
				<mode>Scanning</mode>
				<activeLength unit="deg">3.3473</activeLength>
			</detector>
		</diffractedBeamPath>
		<scan appendNumber="0" mode="Continuous" scanAxis="Gonio" status="Completed">
			<header>
				<startTimeStamp>2016-12-06T11:28:40-05:00</startTimeStamp>
				<endTimeStamp>2016-12-06T11:31:44-05:00</endTimeStamp>
				<author>
					<name>NCSU-XRD</name>
				</author>
				<source>
					<applicationSoftware version="4.2">Data Collector</applicationSoftware>
					<instrumentControlSoftware version="7.6  20140701">EMPYREAN</instrumentControlSoftware>
					<instrumentID>0000000011140639</instrumentID>
				</source>
			</header>
			<dataPoints>
				<positions axis="2Theta" unit="deg">
					<startPosition>36.01203028</startPosition>
					<endPosition>47.98684793</endPosition>
				</positions>
				<positions axis="Omega" unit="deg">
					<startPosition>18.00601514</startPosition>
					<endPosition>23.99342397</endPosition>
				</positions>
				<positions axis="Z" unit="mm">
					<commonPosition>7.161</commonPosition>
				</positions>
				<commonCountingTime unit="seconds">74.715</commonCountingTime>
				<intensities unit="counts">850 884 810 798 875 835 848 876 839 894 871 873 899 796 844 806 857 827 798 869 839 830 855 877 827 820 873 855 838 823 784 812 846 817 791 864 826 846 848 810 837 888 851 828 826 800 860 851 855 852 871 855 870 831 809 816 867 814 918 821 818 846 857 831 842 882 801 966 935 897 953 973 1077 1170 1360 1594 1845 1670 1626 1639 1820 1626 1818 1955 2392 3025 3775 3743 3102 2723 2384 2208 1615 1252 1047 1035 919 880 857 867 945 825 850 868 859 833 823 821 842 803 805 862 825 823 808 777 854 819 814 853 797 848 814 798 781 788 797 817 782 864 846 847 812 844 833 802 788 845 885 834 859 886 806 857 823 815 826 814 796 836 866 778 803 821 821 831 788 828 791 779 774 755 790 779 812 802 801 823 807 834 791 846 778 783 777 750 848 812 801 844 765 827 802 786 761 793 800 810 838 745 783 765 872 847 761 815 817 770 777 741 741 770 777 773 807 790 822 791 780 802 827 769 795 784 847 811 763 787 782 764 783 796 729 731 799 819 803 819 806 785 862 756 813 736 774 755 766 788 796 805 784 810 799 796 783 838 798 770 770 746 802 867 799 798 771 814 775 779 832 845 819 837 792 847 814 819 758 809 853 766 813 808 802 762 803 755 796 807 807 864 832 892 854 794 807 845 823 777 814 771 868 919 834 908 929 895 929 954 995 1057 1088 1075 1104 1145 1249 1277 1319 1461 1546 1737 1893 2091 2304 2582 2877 3078 3226 3689 3767 3945 3910 3888 3908 3619 3453 3048 2887 2555 2224 2130 1854 1669 1417 1319 1250 1147 1093 978 1035 924 952 947 877 894 809 824 903 836 865 830 846 769 838 806 828 829 784 827 808 820 785 766 762 773 783 776 761 761 723 800 773 803 809 794 774 769 835 734 754 841 821 779 801 725 830 782 793 760 756 737 785 784 826 727 784 791 799 766 768 773 812 731 769 777 792 794 777 792 739 762 731 787 789 770 791 801 783 773 759 811 785 761 826 765 776 761 758 730 768 817 787 765 759 796 766 750 764 759 753 759 684 774 781 783 802 845 774 827 754 766 790 818 737 802 746 743 747</intensities>
			</dataPoints>
			<nonAmbientPoints type="Temperature" unit="K">
				<measurementTimes unit="seconds" deltaTime="1">0 59 60 119 120 166 167 184</measurementTimes>
				<nonAmbientValues>298 298 299 299 300 300 301 301</nonAmbientValues>
			</nonAmbientPoints>
		</scan>
		<scan appendNumber="0" mode="Continuous" scanAxis="Gonio" status="Completed">
			<header>
				<startTimeStamp>2016-12-06T11:31:51-05:00</startTimeStamp>
				<endTimeStamp>2016-12-06T11:34:54-05:00</endTimeStamp>
				<author>
					<name>NCSU-XRD</name>
				</author>
				<source>
					<applicationSoftware version="4.2">Data Collector</applicationSoftware>
					<instrumentControlSoftware version="7.6  20140701">EMPYREAN</instrumentControlSoftware>
					<instrumentID>0000000011140639</instrumentID>
				</source>
			</header>
			<dataPoints>
				<positions axis="2Theta" unit="deg">
					<startPosition>36.01203028</startPosition>
					<endPosition>47.98684793</endPosition>
				</positions>
				<positions axis="Omega" unit="deg">
					<startPosition>18.00601514</startPosition>
					<endPosition>23.99342397</endPosition>
				</positions>
				<positions axis="Z" unit="mm">
					<commonPosition>7.161</commonPosition>
				</positions>
				<commonCountingTime unit="seconds">74.715</commonCountingTime>
				<intensities unit="counts">853 814 816 789 882 853 819 805 829 848 771 902 812 799 860 789 777 890 857 839 840 907 830 825 877 850 833 787 758 838 844 851 797 834 878 883 757 818 851 847 839 874 853 889 831 826 822 812 860 856 896 810 826 818 871 867 811 823 865 859 850 871 781 848 898 889 905 865 865 925 972 1007 1019 1126 1353 1610 1819 1705 1598 1662 1740 1661 1817 1922 2374 3126 3736 3622 2971 2600 2462 2139 1630 1296 1064 980 996 927 935 886 884 859 937 872 774 794 862 820 823 807 810 867 813 844 788 813 821 787 833 855 818 841 822 814 787 818 759 812 860 747 798 863 889 825 776 839 780 813 806 867 857 835 806 837 804 846 759 807 802 765 899 812 847 819 791 782 823 793 761 845 778 810 784 765 818 830 836 812 803 822 808 762 766 833 776 790 769 804 818 796 790 776 771 816 837 810 769 757 708 755 845 899 759 830 763 798 844 742 787 819 803 804 793 770 783 796 836 787 869 813 786 779 810 782 778 791 811 808 780 778 768 774 839 771 801 754 797 746 728 815 785 829 821 868 785 774 854 775 825 817 731 758 748 749 781 805 823 732 812 830 771 771 828 811 795 792 810 807 818 769 806 832 835 823 726 829 749 844 779 822 776 796 799 806 850 780 823 878 875 819 842 849 835 832 807 825 850 832 829 832 880 869 863 919 916 907 841 973 940 965 1038 1066 1128 1159 1176 1312 1332 1518 1597 1813 1884 2026 2300 2563 2813 3190 3287 3553 3864 3842 3976 4017 3870 3708 3431 3094 2851 2505 2166 2015 1773 1541 1432 1304 1246 1140 1086 1007 926 921 896 909 876 910 850 819 827 859 800 850 787 837 830 841 782 821 820 774 842 812 814 818 800 814 787 776 784 801 748 795 823 794 769 834 836 797 788 755 824 820 828 817 786 866 813 810 815 861 733 794 758 760 738 837 811 733 741 794 749 774 786 780 758 765 797 830 781 741 774 742 819 771 811 751 786 754 731 775 823 822 772 758 793 756 739 771 749 741 778 776 767 740 774 830 794 767 754 710 830 761 806 770 775 781 737 735 735 716 721 806 762 788 743 761 811 811 732</intensities>
			</dataPoints>
			<nonAmbientPoints type="Temperature" unit="K">
				<measurementTimes unit="seconds" deltaTime="1">0 13 14 50 51 84 85 118 119 150 151 183</measurementTimes>
				<nonAmbientValues>301 301 302 302 303 303 304 304 305 305 306 306</nonAmbientValues>
			</nonAmbientPoints>
		</scan>
		<scan appendNumber="0" mode="Continuous" scanAxis="Gonio" status="Completed">
			<header>
				<startTimeStamp>2016-12-06T11:35:01-05:00</startTimeStamp>
				<endTimeStamp>2016-12-06T11:38:05-05:00</endTimeStamp>
				<author>
					<name>NCSU-XRD</name>
				</author>
				<source>
					<applicationSoftware version="4.2">Data Collector</applicationSoftware>
					<instrumentControlSoftware version="7.6  20140701">EMPYREAN</instrumentControlSoftware>
					<instrumentID>0000000011140639</instrumentID>
				</source>
			</header>
			<dataPoints>
				<positions axis="2Theta" unit="deg">
					<startPosition>36.01203028</startPosition>
					<endPosition>47.98684793</endPosition>
				</positions>
				<positions axis="Omega" unit="deg">
					<startPosition>18.00601514</startPosition>
					<endPosition>23.99342397</endPosition>
				</positions>
				<positions axis="Z" unit="mm">
					<commonPosition>7.161</commonPosition>
				</positions>
				<commonCountingTime unit="seconds">74.715</commonCountingTime>
				<intensities unit="counts">849 806 869 846 860 823 828 876 835 818 792 855 824 784 868 890 887 861 818 875 766 775 815 842 825 776 866 884 807 863 889 828 792 863 859 886 887 896 856 902 826 873 818 820 869 875 769 842 787 832 816 859 810 890 799 869 822 891 754 803 795 851 844 812 842 891 865 838 858 921 894 997 977 1107 1335 1569 1814 1639 1645 1695 1770 1717 1833 1996 2437 3162 3861 3696 3031 2717 2497 2083 1628 1301 1122 1002 953 937 952 896 926 904 894 823 869 819 881 790 761 881 854 849 849 853 854 790 827 872 837 830 794 832 847 803 769 859 792 820 790 821 862 814 844 808 847 832 803 784 836 783 783 815 849 859 831 850 842 761 804 828 811 826 782 804 737 795 811 806 841 837 871 806 796 756 825 757 851 816 800 792 810 782 832 815 759 785 787 821 801 795 822 810 830 796 779 830 782 860 799 850 779 821 832 824 859 712 755 773 853 855 800 797 808 743 784 775 780 783 801 785 820 789 800 849 789 785 813 801 728 777 811 799 824 797 811 758 774 720 765 833 684 753 750 781 760 787 820 783 741 769 819 798 798 806 803 766 806 848 765 794 782 848 771 854 827 763 782 792 777 809 787 806 778 811 795 801 788 788 786 798 768 808 811 862 862 877 807 841 854 798 790 829 824 821 847 785 829 838 835 826 854 862 927 849 869 845 922 1023 1043 953 992 1012 1064 1139 1240 1297 1359 1464 1566 1775 1885 2062 2280 2591 2865 3123 3269 3589 3763 3994 4027 3962 3827 3717 3398 3088 2838 2580 2321 1990 1779 1524 1491 1324 1258 1163 1129 988 979 906 889 957 902 942 825 834 827 821 816 815 846 750 823 849 851 822 801 827 807 766 826 809 793 794 786 779 806 839 822 835 771 778 753 786 847 812 778 805 778 795 772 800 812 740 781 752 779 801 755 781 739 728 824 805 789 774 807 861 800 836 765 772 726 743 822 793 744 756 800 816 782 771 753 811 723 769 802 755 782 758 808 785 740 774 747 769 823 784 796 752 819 798 773 754 787 755 762 791 802 786 792 744 803 776 728 781 772 768 733 763 769 801 782 790 799 766 819</intensities>
			</dataPoints>
			<nonAmbientPoints type="Temperature" unit="K">
				<measurementTimes unit="seconds" deltaTime="1">0 24 25 56 57 86 87 116 117 147 148 177 178 183</measurementTimes>
				<nonAmbientValues>307 307 308 308 309 309 310 310 311 311 312 312 313 313</nonAmbientValues>
			</nonAmbientPoints>
		</scan>
		<scan appendNumber="0" mode="Continuous" scanAxis="Gonio" status="Completed">
			<header>
				<startTimeStamp>2016-12-06T11:38:11-05:00</startTimeStamp>
				<endTimeStamp>2016-12-06T11:41:15-05:00</endTimeStamp>
				<author>
					<name>NCSU-XRD</name>
				</author>
				<source>
					<applicationSoftware version="4.2">Data Collector</applicationSoftware>
					<instrumentControlSoftware version="7.6  20140701">EMPYREAN</instrumentControlSoftware>
					<instrumentID>0000000011140639</instrumentID>
				</source>
			</header>
			<dataPoints>
				<positions axis="2Theta" unit="deg">
					<startPosition>36.01203028</startPosition>
					<endPosition>47.98684793</endPosition>
				</positions>
				<positions axis="Omega" unit="deg">
					<startPosition>18.00601514</startPosition>
					<endPosition>23.99342397</endPosition>
				</positions>
				<positions axis="Z" unit="mm">
					<commonPosition>7.161</commonPosition>
				</positions>
				<commonCountingTime unit="seconds">74.715</commonCountingTime>
				<intensities unit="counts">862 815 871 830 844 820 844 893 825 823 814 819 879 867 862 874 874 864 805 822 854 820 842 834 815 800 838 838 860 820 852 792 821 839 825 850 910 854 822 920 859 792 834 893 851 855 862 934 855 825 869 863 831 874 812 860 823 869 814 827 869 846 852 847 852 841 894 875 880 914 905 1004 1076 1110 1305 1658 1847 1719 1618 1774 1785 1711 1811 2023 2333 3135 3780 3619 2997 2593 2487 2161 1678 1254 1040 1019 985 955 938 785 898 850 866 881 815 857 806 870 854 859 803 820 855 791 780 841 814 766 853 862 819 843 833 811 854 811 776 781 834 804 810 771 866 865 840 815 824 845 783 844 802 796 814 794 779 786 828 810 788 804 809 818 836 784 840 801 840 834 822 757 806 784 776 846 794 785 795 839 795 865 839 800 795 814 799 863 799 819 745 799 757 766 771 822 806 749 752 828 851 771 809 839 881 805 763 829 798 799 824 817 840 803 736 788 788 830 751 751 839 769 795 752 809 814 850 824 806 826 805 795 810 770 766 814 813 776 806 806 842 803 761 784 825 798 795 750 852 789 808 846 802 832 768 815 764 830 854 803 790 814 803 783 721 795 837 854 822 791 846 776 793 834 831 802 778 808 873 837 825 825 794 754 867 789 861 840 816 790 877 869 857 872 871 790 805 765 875 847 862 847 840 880 887 931 885 917 898 965 936 991 1009 1007 1094 1197 1207 1284 1384 1486 1616 1807 1885 2237 2347 2538 2924 3266 3427 3618 3821 3995 3967 4102 3898 3676 3415 3231 2932 2529 2276 2047 1816 1621 1450 1277 1220 1162 1084 1044 973 944 949 871 919 889 799 869 847 853 812 832 807 826 854 811 849 798 784 821 906 801 830 808 779 763 805 829 779 802 804 771 737 787 761 812 806 831 827 841 779 823 741 788 862 753 784 771 814 852 837 727 768 821 760 807 795 801 793 760 830 779 776 807 845 812 787 837 776 796 799 777 778 780 813 752 788 790 739 799 776 778 830 804 811 793 795 855 733 845 776 781 839 720 788 781 818 767 756 766 850 778 749 845 812 771 819 833 804 821 789 841 816 737 744 800 751 748 797</intensities>
			</dataPoints>
			<nonAmbientPoints type="Temperature" unit="K">
				<measurementTimes unit="seconds" deltaTime="1">0 17 18 47 48 77 78 107 108 136 137 167 168 183</measurementTimes>
				<nonAmbientValues>313 313 314 314 315 315 316 316 317 317 318 318 319 319</nonAmbientValues>
			</nonAmbientPoints>
		</scan>
		<scan appendNumber="0" mode="Continuous" scanAxis="Gonio" status="Completed">
			<header>
				<startTimeStamp>2016-12-06T11:41:21-05:00</startTimeStamp>
				<endTimeStamp>2016-12-06T11:44:25-05:00</endTimeStamp>
				<author>
					<name>NCSU-XRD</name>
				</author>
				<source>
					<applicationSoftware version="4.2">Data Collector</applicationSoftware>
					<instrumentControlSoftware version="7.6  20140701">EMPYREAN</instrumentControlSoftware>
					<instrumentID>0000000011140639</instrumentID>
				</source>
			</header>
			<dataPoints>
				<positions axis="2Theta" unit="deg">
					<startPosition>36.01203028</startPosition>
					<endPosition>47.98684793</endPosition>
				</positions>
				<positions axis="Omega" unit="deg">
					<startPosition>18.00601514</startPosition>
					<endPosition>23.99342397</endPosition>
				</positions>
				<positions axis="Z" unit="mm">
					<commonPosition>7.161</commonPosition>
				</positions>
				<commonCountingTime unit="seconds">74.715</commonCountingTime>
				<intensities unit="counts">860 878 884 865 837 844 852 871 871 832 818 838 804 848 842 822 889 829 839 836 781 845 910 878 825 825 868 870 861 850 832 852 842 806 827 841 799 841 874 889 858 836 861 812 800 802 880 783 830 827 820 812 853 808 861 848 863 839 874 897 845 831 932 885 828 878 809 875 883 861 931 994 995 1148 1329 1578 1781 1713 1682 1652 1820 1725 1757 2044 2391 3220 3738 3689 2939 2696 2381 2059 1583 1217 1084 984 945 902 885 881 871 852 837 870 844 790 853 781 851 844 832 834 808 768 830 813 803 828 820 888 807 861 798 785 823 763 875 858 853 827 806 833 828 810 798 794 852 847 807 894 858 763 864 792 858 845 862 823 832 880 865 779 825 800 791 802 771 732 810 812 804 831 799 797 848 806 797 778 745 752 833 771 802 828 817 810 795 822 823 814 781 755 813 716 823 794 816 823 808 779 800 771 789 801 770 815 743 784 830 816 841 771 836 851 745 823 801 800 823 808 798 804 777 845 795 783 826 751 852 779 729 821 786 765 812 809 771 809 795 775 819 822 822 804 802 789 816 811 773 802 788 790 862 801 724 822 779 780 811 811 776 742 834 859 808 759 834 895 773 813 773 798 866 761 773 874 811 790 833 801 769 849 834 789 778 844 789 846 769 804 767 818 879 818 831 829 832 887 872 843 848 857 888 899 843 963 942 893 923 972 1048 1025 1136 1198 1200 1204 1375 1447 1619 1820 1919 2091 2373 2627 2883 3220 3441 3660 3869 3913 4002 3932 3720 3534 3403 3178 2893 2617 2274 2078 1896 1666 1441 1386 1171 1163 1153 1004 974 942 907 952 865 850 846 837 818 794 875 804 823 824 806 834 791 768 804 800 864 771 795 799 826 812 828 731 723 818 780 828 774 810 790 755 757 805 807 777 795 794 854 740 775 781 833 796 787 776 779 779 765 799 775 764 779 725 772 769 754 802 792 793 799 792 790 790 772 776 751 798 784 787 808 730 781 750 794 809 775 745 817 775 716 740 760 773 774 791 774 737 747 824 775 785 847 784 797 765 713 811 749 818 794 753 776 789 779 856 728 813 764 781 815 721 820 764 788</intensities>
			</dataPoints>
			<nonAmbientPoints type="Temperature" unit="K">
				<measurementTimes unit="seconds" deltaTime="1">0 6 7 37 38 66 67 95 96 126 127 155 156 184</measurementTimes>
				<nonAmbientValues>319 319 320 320 321 321 322 322 323 323 324 324 325 325</nonAmbientValues>
			</nonAmbientPoints>
		</scan>
		<scan appendNumber="0" mode="Continuous" scanAxis="Gonio" status="Completed">
			<header>
				<startTimeStamp>2016-12-06T11:44:32-05:00</startTimeStamp>
				<endTimeStamp>2016-12-06T11:47:35-05:00</endTimeStamp>
				<author>
					<name>NCSU-XRD</name>
				</author>
				<source>
					<applicationSoftware version="4.2">Data Collector</applicationSoftware>
					<instrumentControlSoftware version="7.6  20140701">EMPYREAN</instrumentControlSoftware>
					<instrumentID>0000000011140639</instrumentID>
				</source>
			</header>
			<dataPoints>
				<positions axis="2Theta" unit="deg">
					<startPosition>36.01203028</startPosition>
					<endPosition>47.98684793</endPosition>
				</positions>
				<positions axis="Omega" unit="deg">
					<startPosition>18.00601514</startPosition>
					<endPosition>23.99342397</endPosition>
				</positions>
				<positions axis="Z" unit="mm">
					<commonPosition>7.161</commonPosition>
				</positions>
				<commonCountingTime unit="seconds">74.715</commonCountingTime>
				<intensities unit="counts">807 831 914 847 795 884 819 872 830 829 802 844 853 790 839 815 800 837 825 838 825 792 842 856 839 844 854 828 827 864 835 763 852 901 860 784 841 886 863 896 836 918 802 904 832 857 865 818 830 825 866 846 814 807 871 802 839 850 834 760 831 820 857 827 878 872 875 868 845 901 922 984 1043 1161 1268 1604 1792 1799 1633 1653 1741 1702 1783 2030 2569 3211 3776 3727 2991 2651 2483 2023 1625 1268 1045 1001 930 926 932 916 864 924 798 875 860 823 828 820 889 847 814 784 771 852 846 897 867 864 809 815 853 853 821 775 834 807 753 827 804 849 823 826 785 811 806 835 822 789 832 796 817 813 782 787 798 779 820 778 857 788 849 785 767 797 805 785 743 895 787 818 817 804 858 815 820 819 848 811 828 818 767 766 771 794 798 762 769 783 832 814 836 796 816 820 774 809 796 807 804 829 808 815 838 795 776 866 843 790 796 775 823 804 803 798 830 838 831 819 844 795 774 795 772 750 770 760 825 766 784 775 763 763 758 839 781 798 804 772 800 787 796 764 785 800 826 737 755 847 815 788 810 753 775 780 797 805 812 809 760 813 836 807 758 784 820 772 800 802 780 782 775 840 871 835 786 772 842 832 751 791 866 823 882 763 793 837 814 862 842 837 814 805 848 862 839 791 851 829 874 861 865 879 842 920 884 957 913 986 970 1006 1054 1056 1093 1201 1169 1284 1416 1567 1520 1787 1926 2065 2424 2561 2818 2961 3452 3567 3632 3959 3933 4114 3801 3665 3474 3173 2816 2510 2331 2057 1736 1661 1413 1348 1233 1199 1048 986 937 998 900 897 874 854 832 855 848 874 814 805 834 845 772 837 822 801 817 906 850 842 822 767 776 789 803 783 814 854 783 823 830 814 798 819 760 778 774 816 813 801 827 794 818 804 809 755 809 787 758 822 819 755 771 771 786 728 741 803 751 759 812 816 765 786 748 784 770 773 811 769 776 747 751 877 743 771 807 788 781 776 776 792 793 816 766 743 736 795 740 753 754 724 808 793 712 738 797 779 777 721 787 728 753 843 788 804 812 764 745 744 810 847 741 749 778 786 755</intensities>
			</dataPoints>
			<nonAmbientPoints type="Temperature" unit="K">
				<measurementTimes unit="seconds" deltaTime="1">0 24 25 54 55 84 85 114 115 143 144 173 174 183</measurementTimes>
				<nonAmbientValues>326 326 327 327 328 328 329 329 330 330 331 331 332 332</nonAmbientValues>
			</nonAmbientPoints>
		</scan>
		<scan appendNumber="0" mode="Continuous" scanAxis="Gonio" status="Completed">
			<header>
				<startTimeStamp>2016-12-06T11:47:42-05:00</startTimeStamp>
				<endTimeStamp>2016-12-06T11:50:46-05:00</endTimeStamp>
				<author>
					<name>NCSU-XRD</name>
				</author>
				<source>
					<applicationSoftware version="4.2">Data Collector</applicationSoftware>
					<instrumentControlSoftware version="7.6  20140701">EMPYREAN</instrumentControlSoftware>
					<instrumentID>0000000011140639</instrumentID>
				</source>
			</header>
			<dataPoints>
				<positions axis="2Theta" unit="deg">
					<startPosition>36.01203028</startPosition>
					<endPosition>47.98684793</endPosition>
				</positions>
				<positions axis="Omega" unit="deg">
					<startPosition>18.00601514</startPosition>
					<endPosition>23.99342397</endPosition>
				</positions>
				<positions axis="Z" unit="mm">
					<commonPosition>7.161</commonPosition>
				</positions>
				<commonCountingTime unit="seconds">74.715</commonCountingTime>
				<intensities unit="counts">841 827 855 795 823 883 863 761 889 806 803 796 905 842 876 785 825 804 866 786 840 748 830 792 814 806 842 868 896 772 783 823 809 804 849 841 857 855 865 852 859 798 816 761 834 862 818 785 840 830 845 868 804 867 846 782 828 822 824 862 789 808 908 860 859 801 805 874 881 941 903 923 1002 1121 1212 1527 1748 1786 1648 1647 1826 1802 1710 2080 2481 3079 3801 3556 3010 2580 2378 2172 1585 1175 1031 936 989 925 892 828 840 803 833 829 847 892 856 857 854 842 803 824 791 891 849 813 792 829 745 870 804 812 836 862 886 762 818 799 865 735 811 813 802 796 858 841 782 848 843 837 779 777 807 760 804 811 774 820 818 792 828 851 841 780 811 753 813 832 858 833 824 819 808 817 812 766 816 775 834 834 793 793 783 843 759 813 826 821 802 796 776 781 792 795 796 787 767 755 796 789 782 750 787 837 813 776 800 771 775 793 773 801 783 801 802 769 777 795 766 857 784 806 791 764 779 790 729 790 797 766 748 766 825 729 746 752 803 807 787 737 772 742 795 805 755 777 810 831 812 787 803 824 734 760 775 795 817 766 775 757 778 790 828 799 735 879 803 741 826 805 800 829 819 796 784 818 821 813 797 787 770 799 805 845 797 783 795 838 774 812 785 801 786 793 836 809 775 844 836 836 876 849 857 864 915 894 956 922 979 1017 989 1064 1085 1163 1292 1274 1424 1469 1565 1742 1925 2134 2311 2536 2823 3156 3391 3663 3814 3804 3952 3847 3808 3571 3353 3234 2828 2604 2249 1933 1844 1622 1441 1293 1246 1128 1072 998 983 973 970 909 944 893 814 880 857 842 821 810 813 890 799 828 798 850 814 792 816 774 773 821 771 761 824 885 821 747 821 831 823 765 832 784 787 752 807 801 758 784 753 800 792 742 762 736 821 800 760 793 755 789 758 760 793 776 816 769 812 765 783 800 774 749 800 751 766 786 759 734 789 793 775 795 749 802 806 738 744 803 746 788 810 758 774 791 781 743 775 756 799 826 797 792 761 755 755 839 777 778 771 781 765 756 815 797 778 826 767 803 714 821 793 728 762 784 777</intensities>
			</dataPoints>
			<nonAmbientPoints type="Temperature" unit="K">
				<measurementTimes unit="seconds" deltaTime="1">0 14 15 44 45 73 74 104 105 134 135 164 165 184</measurementTimes>
				<nonAmbientValues>332 332 333 333 334 334 335 335 336 336 337 337 338 338</nonAmbientValues>
			</nonAmbientPoints>
		</scan>
		<scan appendNumber="0" mode="Continuous" scanAxis="Gonio" status="Completed">
			<header>
				<startTimeStamp>2016-12-06T11:50:52-05:00</startTimeStamp>
				<endTimeStamp>2016-12-06T11:53:56-05:00</endTimeStamp>
				<author>
					<name>NCSU-XRD</name>
				</author>
				<source>
					<applicationSoftware version="4.2">Data Collector</applicationSoftware>
					<instrumentControlSoftware version="7.6  20140701">EMPYREAN</instrumentControlSoftware>
					<instrumentID>0000000011140639</instrumentID>
				</source>
			</header>
			<dataPoints>
				<positions axis="2Theta" unit="deg">
					<startPosition>36.01203028</startPosition>
					<endPosition>47.98684793</endPosition>
				</positions>
				<positions axis="Omega" unit="deg">
					<startPosition>18.00601514</startPosition>
					<endPosition>23.99342397</endPosition>
				</positions>
				<positions axis="Z" unit="mm">
					<commonPosition>7.161</commonPosition>
				</positions>
				<commonCountingTime unit="seconds">74.715</commonCountingTime>
				<intensities unit="counts">861 812 844 835 868 794 833 797 785 800 842 866 784 817 810 809 873 800 824 836 808 888 827 849 809 855 788 846 854 813 820 862 845 806 847 867 806 880 875 787 832 807 826 794 790 852 834 821 795 907 824 825 853 849 834 834 820 805 860 860 849 805 879 865 911 923 910 881 899 872 874 975 1037 1061 1219 1470 1746 1770 1670 1689 1755 1852 1867 2022 2492 3160 3825 3724 2910 2586 2322 2100 1612 1140 1062 972 964 858 919 868 840 852 836 821 844 866 864 801 836 858 805 811 869 839 774 778 824 878 833 831 829 821 856 827 888 836 851 820 786 878 786 797 864 864 832 840 774 831 806 806 789 835 771 819 765 834 798 846 759 833 790 791 776 844 752 782 809 865 802 803 744 733 826 836 796 816 793 782 831 790 862 827 740 785 774 793 802 729 799 834 770 823 774 801 817 756 828 837 826 809 723 822 742 739 805 846 839 757 783 812 723 811 790 792 841 725 785 784 782 789 738 745 810 776 871 790 811 773 773 807 787 780 803 782 823 794 775 841 783 770 783 822 734 800 736 771 790 787 818 748 790 801 777 772 823 811 795 808 815 800 791 783 835 782 788 805 776 770 800 804 801 786 801 863 813 849 830 824 824 750 835 848 750 859 757 860 822 799 797 774 818 805 820 808 843 846 858 841 896 827 866 873 863 863 846 957 921 913 981 980 1019 1061 1076 1172 1185 1247 1387 1451 1656 1754 1948 2189 2429 2605 2841 3130 3347 3589 3789 3982 4048 4030 3760 3713 3404 3132 2835 2583 2350 2109 1815 1500 1506 1267 1228 1120 1069 1091 990 951 975 917 879 905 920 848 864 840 875 876 772 812 847 824 757 797 830 826 814 825 779 861 781 760 768 802 796 778 812 803 771 875 862 795 824 786 779 758 769 857 811 818 784 811 745 774 786 798 768 793 769 759 778 817 739 793 786 762 718 748 747 778 786 767 798 749 778 777 798 770 781 794 754 777 752 772 793 782 794 779 817 817 791 796 736 794 773 811 804 771 783 764 773 811 807 773 778 791 813 813 763 756 735 791 760 771 752 712 780 771 809 765 787 835 825 831 806</intensities>
			</dataPoints>
			<nonAmbientPoints type="Temperature" unit="K">
				<measurementTimes unit="seconds" deltaTime="1">0 2 3 31 32 62 63 92 93 122 123 152 153 181 182 183</measurementTimes>
				<nonAmbientValues>338 338 339 339 340 340 341 341 342 342 343 343 344 344 345 345</nonAmbientValues>
			</nonAmbientPoints>
		</scan>
		<scan appendNumber="0" mode="Continuous" scanAxis="Gonio" status="Completed">
			<header>
				<startTimeStamp>2016-12-06T11:54:02-05:00</startTimeStamp>
				<endTimeStamp>2016-12-06T11:57:06-05:00</endTimeStamp>
				<author>
					<name>NCSU-XRD</name>
				</author>
				<source>
					<applicationSoftware version="4.2">Data Collector</applicationSoftware>
					<instrumentControlSoftware version="7.6  20140701">EMPYREAN</instrumentControlSoftware>
					<instrumentID>0000000011140639</instrumentID>
				</source>
			</header>
			<dataPoints>
				<positions axis="2Theta" unit="deg">
					<startPosition>36.01203028</startPosition>
					<endPosition>47.98684793</endPosition>
				</positions>
				<positions axis="Omega" unit="deg">
					<startPosition>18.00601514</startPosition>
					<endPosition>23.99342397</endPosition>
				</positions>
				<positions axis="Z" unit="mm">
					<commonPosition>7.161</commonPosition>
				</positions>
				<commonCountingTime unit="seconds">74.715</commonCountingTime>
				<intensities unit="counts">821 872 852 797 867 821 831 835 880 828 842 819 817 824 785 794 832 823 834 782 833 838 855 799 812 855 866 827 845 840 848 814 818 826 883 868 794 840 799 823 910 862 905 819 859 885 782 817 833 822 850 884 881 828 838 795 844 825 891 874 812 852 901 854 897 882 827 850 853 872 884 981 992 1038 1203 1457 1702 1772 1723 1680 1826 1812 1845 2086 2576 3145 3945 3692 2918 2560 2480 2069 1600 1177 1002 1022 967 912 887 911 835 886 843 891 814 882 848 863 783 858 811 807 824 845 830 840 843 826 824 769 781 823 868 809 833 839 863 856 800 888 809 800 815 821 823 763 826 769 798 823 803 810 791 842 801 817 818 805 823 799 888 808 829 844 824 786 818 824 811 784 840 829 808 819 843 788 745 821 795 843 766 825 740 798 766 826 787 803 772 771 850 822 838 826 771 811 804 794 825 773 850 819 828 734 746 793 842 825 807 834 832 794 753 811 752 763 822 791 825 737 808 782 781 803 757 806 782 830 812 777 762 775 797 794 801 860 781 812 795 751 802 795 811 821 838 766 803 803 724 781 758 815 799 798 777 773 834 739 843 805 780 789 766 812 813 837 833 778 850 866 881 797 842 764 843 820 803 804 809 815 785 799 809 877 824 792 832 810 834 774 822 799 804 783 838 818 849 806 875 872 912 930 924 920 944 850 933 954 938 945 1026 1060 1022 1139 1219 1288 1357 1465 1652 1801 2013 2123 2261 2567 2947 3143 3331 3645 3745 3958 4045 3832 3929 3703 3286 3213 2858 2596 2222 2020 1808 1643 1513 1350 1303 1214 1061 988 943 1009 918 906 882 876 842 861 775 844 846 807 833 869 847 818 793 839 797 846 825 813 829 830 812 786 841 800 830 771 783 753 783 810 780 816 845 827 768 767 794 800 807 794 786 815 736 812 806 763 867 783 776 806 798 712 752 775 755 753 763 778 777 783 809 794 766 737 813 786 795 763 738 757 799 840 723 788 765 764 737 788 721 782 752 779 768 801 781 770 760 780 830 792 730 813 820 764 767 778 726 782 773 749 805 775 771 791 765 756 761 757 797 748 775 779 728 734 798</intensities>
			</dataPoints>
			<nonAmbientPoints type="Temperature" unit="K">
				<measurementTimes unit="seconds" deltaTime="1">0 21 22 51 52 80 81 110 111 139 140 161 162 182</measurementTimes>
				<nonAmbientValues>345 345 346 346 347 347 348 348 349 349 350 350 351 351</nonAmbientValues>
			</nonAmbientPoints>
		</scan>
		<scan appendNumber="0" mode="Continuous" scanAxis="Gonio" status="Completed">
			<header>
				<startTimeStamp>2016-12-06T11:57:12-05:00</startTimeStamp>
				<endTimeStamp>2016-12-06T12:00:16-05:00</endTimeStamp>
				<author>
					<name>NCSU-XRD</name>
				</author>
				<source>
					<applicationSoftware version="4.2">Data Collector</applicationSoftware>
					<instrumentControlSoftware version="7.6  20140701">EMPYREAN</instrumentControlSoftware>
					<instrumentID>0000000011140639</instrumentID>
				</source>
			</header>
			<dataPoints>
				<positions axis="2Theta" unit="deg">
					<startPosition>36.01203028</startPosition>
					<endPosition>47.98684793</endPosition>
				</positions>
				<positions axis="Omega" unit="deg">
					<startPosition>18.00601514</startPosition>
					<endPosition>23.99342397</endPosition>
				</positions>
				<positions axis="Z" unit="mm">
					<commonPosition>7.161</commonPosition>
				</positions>
				<commonCountingTime unit="seconds">74.715</commonCountingTime>
				<intensities unit="counts">886 792 797 834 823 791 828 786 846 810 837 826 801 822 851 823 749 841 827 849 811 881 845 780 893 846 804 807 878 891 817 850 853 904 892 799 830 829 812 912 875 867 828 878 812 873 889 814 892 835 849 855 850 832 919 840 858 887 862 788 874 868 880 792 841 833 840 922 876 869 940 922 1001 1036 1158 1425 1648 1854 1714 1724 1836 1857 1904 2145 2574 3238 3628 3631 2996 2503 2419 2011 1524 1271 1058 1004 953 936 821 881 873 879 816 891 839 845 776 853 809 857 818 819 771 823 795 827 863 796 775 801 805 879 782 834 804 790 809 818 837 780 771 793 833 810 857 825 821 802 796 804 769 804 813 818 823 886 813 839 787 823 825 854 850 834 765 808 842 818 822 869 788 828 839 818 846 792 804 810 838 780 806 844 805 776 792 732 790 823 779 787 815 770 857 829 790 798 843 833 761 782 785 820 824 822 802 798 780 759 802 809 841 803 762 766 843 771 751 760 789 754 832 790 842 798 833 820 815 841 823 812 767 797 739 727 767 759 747 771 785 793 793 774 800 810 789 798 812 827 799 821 823 794 742 832 788 801 816 826 795 740 752 789 791 840 821 781 789 882 809 808 827 758 840 778 785 810 830 811 832 880 822 798 820 812 770 730 774 808 868 815 869 809 811 738 780 780 795 843 826 860 933 884 859 862 925 948 970 881 1035 978 988 998 1096 1138 1159 1312 1372 1476 1562 1717 1968 2047 2412 2550 2834 3042 3394 3711 3829 3889 3921 3911 3730 3685 3378 3075 2830 2609 2252 2035 1824 1600 1466 1371 1207 1107 1086 996 1029 894 893 860 886 837 848 815 897 813 851 855 826 813 783 782 819 865 805 837 837 853 760 793 764 847 807 797 809 768 833 810 781 803 797 767 832 832 820 715 754 831 831 842 801 812 704 801 831 848 747 763 760 843 810 829 756 759 820 759 811 755 756 802 756 795 794 775 723 779 782 809 775 770 776 773 748 711 792 781 800 793 781 807 759 809 787 792 765 754 795 815 746 736 766 772 751 761 744 798 791 790 781 785 761 764 731 766 782 771 775 794 790 785 793 822 769 741 750</intensities>
			</dataPoints>
			<nonAmbientPoints type="Temperature" unit="K">
				<measurementTimes unit="seconds" deltaTime="1">0 25 26 51 52 80 81 109 110 139 140 171 172 184</measurementTimes>
				<nonAmbientValues>352 352 353 353 354 354 355 355 356 356 357 357 358 358</nonAmbientValues>
			</nonAmbientPoints>
		</scan>
		<scan appendNumber="0" mode="Continuous" scanAxis="Gonio" status="Completed">
			<header>
				<startTimeStamp>2016-12-06T12:00:23-05:00</startTimeStamp>
				<endTimeStamp>2016-12-06T12:03:26-05:00</endTimeStamp>
				<author>
					<name>NCSU-XRD</name>
				</author>
				<source>
					<applicationSoftware version="4.2">Data Collector</applicationSoftware>
					<instrumentControlSoftware version="7.6  20140701">EMPYREAN</instrumentControlSoftware>
					<instrumentID>0000000011140639</instrumentID>
				</source>
			</header>
			<dataPoints>
				<positions axis="2Theta" unit="deg">
					<startPosition>36.01203028</startPosition>
					<endPosition>47.98684793</endPosition>
				</positions>
				<positions axis="Omega" unit="deg">
					<startPosition>18.00601514</startPosition>
					<endPosition>23.99342397</endPosition>
				</positions>
				<positions axis="Z" unit="mm">
					<commonPosition>7.161</commonPosition>
				</positions>
				<commonCountingTime unit="seconds">74.715</commonCountingTime>
				<intensities unit="counts">826 795 856 832 841 811 879 844 814 885 810 823 856 845 799 825 834 872 845 827 858 833 816 825 809 786 881 832 824 847 838 866 823 845 815 797 865 846 881 833 823 896 830 829 891 884 872 810 891 831 833 846 791 864 851 813 758 893 869 802 852 856 795 851 874 821 887 875 868 865 925 875 1004 1023 1130 1367 1789 1874 1663 1693 1783 1921 1925 2086 2583 3156 3826 3534 2821 2473 2454 2128 1587 1179 1020 1005 974 912 936 857 823 874 882 867 883 800 873 873 788 763 815 829 863 863 821 819 819 874 848 843 752 798 772 760 766 829 834 872 804 757 838 797 829 788 780 789 843 846 791 790 779 837 803 815 824 798 868 836 850 827 810 830 867 825 837 821 853 799 811 767 750 759 815 797 806 862 817 793 765 807 770 791 745 823 741 824 818 796 838 780 813 782 787 818 800 823 867 822 812 700 800 795 762 763 825 829 767 792 759 819 822 777 831 855 786 780 796 791 790 784 859 855 799 781 812 747 780 748 750 752 733 788 793 868 754 778 823 801 759 770 751 789 794 775 780 793 763 821 767 789 804 829 763 822 789 808 776 725 774 827 772 843 769 809 767 806 821 768 830 835 867 802 816 793 820 824 776 774 825 854 874 878 923 907 802 808 882 830 831 814 849 850 835 761 837 796 827 817 849 854 863 885 832 906 941 898 951 918 1010 1035 1060 965 1138 1232 1321 1350 1464 1496 1590 1776 1944 2169 2318 2557 2846 3106 3410 3589 3889 3859 3931 3740 3618 3560 3436 3097 2758 2473 2280 2011 1823 1663 1456 1320 1178 1151 1103 992 951 905 920 870 869 898 880 800 830 777 802 804 821 870 816 776 791 829 799 855 806 807 808 788 764 739 788 854 788 815 789 827 783 788 806 828 804 753 786 833 781 780 748 799 814 783 793 828 801 799 757 790 806 763 729 763 796 744 791 800 764 772 780 799 795 749 793 791 802 847 723 759 801 713 741 803 789 767 809 792 783 853 779 782 760 769 799 834 804 878 801 741 756 816 805 795 790 788 797 767 834 777 745 764 833 788 776 779 811 795 806 770 796 845 755 709 758 796 765</intensities>
			</dataPoints>
			<nonAmbientPoints type="Temperature" unit="K">
				<measurementTimes unit="seconds" deltaTime="1">0 11 12 40 41 73 74 104 105 136 137 167 168 183</measurementTimes>
				<nonAmbientValues>358 358 359 359 360 360 361 361 362 362 363 363 364 364</nonAmbientValues>
			</nonAmbientPoints>
		</scan>
		<scan appendNumber="0" mode="Continuous" scanAxis="Gonio" status="Completed">
			<header>
				<startTimeStamp>2016-12-06T12:03:33-05:00</startTimeStamp>
				<endTimeStamp>2016-12-06T12:06:37-05:00</endTimeStamp>
				<author>
					<name>NCSU-XRD</name>
				</author>
				<source>
					<applicationSoftware version="4.2">Data Collector</applicationSoftware>
					<instrumentControlSoftware version="7.6  20140701">EMPYREAN</instrumentControlSoftware>
					<instrumentID>0000000011140639</instrumentID>
				</source>
			</header>
			<dataPoints>
				<positions axis="2Theta" unit="deg">
					<startPosition>36.01203028</startPosition>
					<endPosition>47.98684793</endPosition>
[...]
			</dataPoints>
			<nonAmbientPoints type="Temperature" unit="K">
				<measurementTimes unit="seconds" deltaTime="1">0 19 20 48 49 77 78 106 107 135 136 166 167 183</measurementTimes>
				<nonAmbientValues>690 690 691 691 692 692 693 693 694 694 695 695 696 696</nonAmbientValues>
			</nonAmbientPoints>
		</scan>
		<scan appendNumber="0" mode="Continuous" scanAxis="Gonio" status="Completed">
			<header>
				<startTimeStamp>2016-12-06T14:48:24-05:00</startTimeStamp>
				<endTimeStamp>2016-12-06T14:51:28-05:00</endTimeStamp>
				<author>
					<name>NCSU-XRD</name>
				</author>
				<source>
					<applicationSoftware version="4.2">Data Collector</applicationSoftware>
					<instrumentControlSoftware version="7.6  20140701">EMPYREAN</instrumentControlSoftware>
					<instrumentID>0000000011140639</instrumentID>
				</source>
			</header>
			<dataPoints>
				<positions axis="2Theta" unit="deg">
					<startPosition>36.01203028</startPosition>
					<endPosition>47.98684793</endPosition>
				</positions>
				<positions axis="Omega" unit="deg">
					<startPosition>18.00601514</startPosition>
					<endPosition>23.99342397</endPosition>
				</positions>
				<positions axis="Z" unit="mm">
					<commonPosition>7.161</commonPosition>
				</positions>
				<commonCountingTime unit="seconds">74.715</commonCountingTime>
				<intensities unit="counts">877 904 854 878 865 894 809 854 852 820 819 848 875 865 822 858 907 858 866 944 838 907 841 849 863 916 874 824 872 865 850 879 912 862 886 887 812 859 936 870 869 867 849 894 809 851 855 827 799 840 852 825 859 902 866 845 875 820 827 869 807 873 900 869 861 896 880 873 920 917 888 892 876 924 855 957 1014 1079 1098 1297 1533 1875 2229 2878 3745 4185 3652 3061 2974 2661 2092 1586 1317 1178 1058 1009 952 942 904 871 901 908 871 847 909 868 925 820 818 914 884 837 843 854 828 857 849 860 825 881 873 851 881 847 859 879 898 861 792 828 861 841 812 791 777 852 853 871 812 864 860 813 836 789 802 861 824 871 757 864 846 871 822 802 859 841 874 878 840 873 799 860 826 801 857 790 801 792 788 819 867 825 798 818 831 838 876 813 783 806 849 869 842 844 846 773 792 814 847 868 828 826 785 857 786 782 835 822 897 898 828 835 771 818 836 858 809 859 755 834 791 821 860 811 771 799 791 797 834 830 820 869 854 855 828 905 814 824 857 799 877 805 806 810 923 852 896 800 780 831 832 789 819 802 830 858 818 808 816 877 881 846 792 818 839 810 875 835 801 867 844 804 870 852 864 860 865 862 913 795 841 858 828 780 857 796 856 815 835 834 865 818 848 824 859 844 804 842 850 910 901 839 889 837 868 816 901 878 858 885 892 887 931 919 878 961 937 984 1008 1021 1202 1165 1400 1438 1679 1905 2393 3053 3882 5114 6273 6512 5590 4736 4631 4364 3607 2746 2200 1734 1434 1265 1225 998 977 895 951 926 947 949 916 943 917 848 896 890 880 844 846 902 835 862 844 840 848 838 873 863 788 881 842 816 837 843 853 839 868 881 831 871 785 804 847 841 849 865 806 823 744 862 803 786 836 813 824 814 881 826 866 809 812 795 834 844 781 797 744 835 833 822 809 852 829 783 801 840 781 776 811 812 827 782 836 832 864 843 781 768 876 804 810 823 743 825 783 918 811 823 743 806 784 878 867 880 752 800 868 825 811 792 780 847 805 742 828 848 792 813 837 838 793 775 814 826 773 817 806</intensities>
			</dataPoints>
			<nonAmbientPoints type="Temperature" unit="K">
				<measurementTimes unit="seconds" deltaTime="1">0 5 6 35 36 65 66 95 96 126 127 155 156 184</measurementTimes>
				<nonAmbientValues>696 696 697 697 698 698 699 699 700 700 701 701 702 702</nonAmbientValues>
			</nonAmbientPoints>
		</scan>
		<scan appendNumber="0" mode="Continuous" scanAxis="Gonio" status="Completed">
			<header>
				<startTimeStamp>2016-12-06T14:51:34-05:00</startTimeStamp>
				<endTimeStamp>2016-12-06T14:54:38-05:00</endTimeStamp>
				<author>
					<name>NCSU-XRD</name>
				</author>
				<source>
					<applicationSoftware version="4.2">Data Collector</applicationSoftware>
					<instrumentControlSoftware version="7.6  20140701">EMPYREAN</instrumentControlSoftware>
					<instrumentID>0000000011140639</instrumentID>
				</source>
			</header>
			<dataPoints>
				<positions axis="2Theta" unit="deg">
					<startPosition>36.01203028</startPosition>
					<endPosition>47.98684793</endPosition>
				</positions>
				<positions axis="Omega" unit="deg">
					<startPosition>18.00601514</startPosition>
					<endPosition>23.99342397</endPosition>
				</positions>
				<positions axis="Z" unit="mm">
					<commonPosition>7.161</commonPosition>
				</positions>
				<commonCountingTime unit="seconds">74.715</commonCountingTime>
				<intensities unit="counts">838 871 862 777 904 807 827 839 849 886 928 831 882 819 835 810 799 841 884 847 792 865 871 862 852 949 855 847 770 894 828 874 850 842 846 837 896 917 832 854 876 841 904 857 891 839 874 837 916 877 884 849 889 875 864 914 875 848 890 883 876 846 891 907 852 798 887 944 868 879 878 914 867 941 970 902 966 1052 1235 1258 1492 1770 2200 2969 3704 4111 3490 2956 2911 2651 1996 1657 1326 1166 1063 1055 917 980 968 883 854 860 837 862 844 911 858 832 872 889 837 824 869 812 902 834 812 889 903 904 786 850 794 856 815 897 884 836 877 815 862 805 877 877 805 842 858 870 819 796 837 844 855 837 834 867 801 892 845 837 815 874 771 846 811 853 848 851 883 805 867 852 800 815 850 874 811 847 836 841 825 854 785 824 824 834 844 819 838 828 866 834 859 804 833 890 835 799 815 837 829 879 847 797 858 824 790 792 841 831 795 846 826 759 785 805 785 868 884 797 833 799 845 871 904 825 812 835 845 830 770 837 840 806 833 883 824 785 848 855 810 795 823 841 874 803 823 797 813 775 829 827 803 797 758 789 771 822 825 842 833 816 818 831 828 792 902 840 860 862 860 823 873 866 807 834 884 838 836 896 811 866 849 835 861 892 833 810 856 868 877 887 883 863 828 918 875 861 894 849 810 833 865 916 896 802 864 839 874 822 893 930 882 912 955 991 948 928 1054 1054 1197 1213 1328 1494 1688 1921 2343 2960 3870 5083 6318 6505 5608 4804 4625 4261 3662 2753 2067 1728 1479 1254 1204 1065 1018 987 986 963 938 911 844 938 887 913 909 888 927 809 883 827 849 848 897 869 867 882 920 821 836 801 800 861 845 810 873 787 805 840 807 852 912 856 871 853 836 840 840 850 811 841 823 849 797 818 850 794 865 866 862 892 876 822 798 813 781 862 804 802 805 825 848 853 823 820 854 877 779 871 857 812 816 849 813 816 841 821 839 784 825 841 849 869 769 833 843 782 842 880 846 820 872 842 856 830 776 807 820 795 870 777 824 894 802 810 792 812 877 836 832 885 772 803 864 822 822 825 837</intensities>
			</dataPoints>
			<nonAmbientPoints type="Temperature" unit="K">
				<measurementTimes unit="seconds" deltaTime="1">0 23 24 53 54 84 85 113 114 144 145 174 175 182</measurementTimes>
				<nonAmbientValues>703 703 704 704 705 705 706 706 707 707 708 708 709 709</nonAmbientValues>
			</nonAmbientPoints>
		</scan>
		<scan appendNumber="0" mode="Continuous" scanAxis="Gonio" status="Completed">
			<header>
				<startTimeStamp>2016-12-06T14:54:45-05:00</startTimeStamp>
				<endTimeStamp>2016-12-06T14:57:48-05:00</endTimeStamp>
				<author>
					<name>NCSU-XRD</name>
				</author>
				<source>
					<applicationSoftware version="4.2">Data Collector</applicationSoftware>
					<instrumentControlSoftware version="7.6  20140701">EMPYREAN</instrumentControlSoftware>
					<instrumentID>0000000011140639</instrumentID>
				</source>
			</header>
			<dataPoints>
				<positions axis="2Theta" unit="deg">
					<startPosition>36.01203028</startPosition>
					<endPosition>47.98684793</endPosition>
				</positions>
				<positions axis="Omega" unit="deg">
					<startPosition>18.00601514</startPosition>
					<endPosition>23.99342397</endPosition>
				</positions>
				<positions axis="Z" unit="mm">
					<commonPosition>7.161</commonPosition>
				</positions>
				<commonCountingTime unit="seconds">74.715</commonCountingTime>
				<intensities unit="counts">931 865 900 866 876 915 822 818 851 885 822 844 857 840 838 844 850 848 833 813 870 909 850 889 852 846 882 835 828 870 905 835 826 813 859 882 857 813 825 883 934 896 916 846 874 932 795 885 850 870 875 889 859 839 853 851 874 900 922 851 868 858 867 874 866 851 850 854 920 844 931 872 991 886 918 929 966 1041 1197 1287 1458 1746 2347 3008 3663 4109 3471 2987 2949 2623 2117 1586 1310 1136 1086 1007 976 917 862 905 891 934 904 839 884 838 897 844 904 837 888 832 852 817 909 855 853 883 885 843 845 836 822 812 825 859 873 897 847 878 837 834 876 827 856 879 804 863 842 865 855 866 806 914 838 844 865 812 851 855 814 874 897 858 836 841 810 809 822 863 836 811 859 825 847 830 848 893 844 811 819 900 868 834 858 820 834 816 867 811 852 794 780 823 758 884 897 826 746 840 844 843 810 820 793 823 801 826 801 780 891 815 839 777 855 860 850 830 812 841 809 831 802 824 859 913 823 763 852 830 883 816 835 819 825 844 779 809 758 827 836 810 832 850 849 869 849 805 862 796 820 793 828 846 890 825 841 878 845 816 794 802 842 852 825 835 792 846 873 857 812 848 924 883 820 868 910 852 816 809 879 860 830 825 826 841 861 824 826 826 853 872 866 915 830 871 865 847 836 837 787 882 894 817 863 854 894 889 886 882 897 886 921 881 900 990 989 1022 987 1080 1088 1244 1314 1378 1616 1964 2339 2930 3905 5053 6247 6450 5642 4884 4552 4368 3510 2716 2147 1781 1450 1291 1155 1125 1005 985 972 1003 928 882 849 862 879 886 882 848 827 793 848 857 842 860 907 843 883 860 853 840 858 869 858 850 844 843 845 830 826 833 817 869 871 857 808 831 848 771 861 827 831 743 894 783 847 862 814 843 789 795 806 799 811 801 828 787 823 800 866 868 836 741 820 875 810 819 832 816 855 843 816 915 810 850 828 833 862 851 854 838 830 860 853 822 807 816 867 797 868 837 900 823 853 756 865 843 862 830 782 864 818 799 808 817 868 806 791 841 812 795 863 850 832 863 782 841 839 822 791</intensities>
			</dataPoints>
			<nonAmbientPoints type="Temperature" unit="K">
				<measurementTimes unit="seconds" deltaTime="1">0 14 15 44 45 74 75 104 105 134 135 165 166 184</measurementTimes>
				<nonAmbientValues>709 709 710 710 711 711 712 712 713 713 714 714 715 715</nonAmbientValues>
			</nonAmbientPoints>
		</scan>
		<scan appendNumber="0" mode="Continuous" scanAxis="Gonio" status="Completed">
			<header>
				<startTimeStamp>2016-12-06T14:57:55-05:00</startTimeStamp>
				<endTimeStamp>2016-12-06T15:00:59-05:00</endTimeStamp>
				<author>
					<name>NCSU-XRD</name>
				</author>
				<source>
					<applicationSoftware version="4.2">Data Collector</applicationSoftware>
					<instrumentControlSoftware version="7.6  20140701">EMPYREAN</instrumentControlSoftware>
					<instrumentID>0000000011140639</instrumentID>
				</source>
			</header>
			<dataPoints>
				<positions axis="2Theta" unit="deg">
					<startPosition>36.01203028</startPosition>
					<endPosition>47.98684793</endPosition>
				</positions>
				<positions axis="Omega" unit="deg">
					<startPosition>18.00601514</startPosition>
					<endPosition>23.99342397</endPosition>
				</positions>
				<positions axis="Z" unit="mm">
					<commonPosition>7.161</commonPosition>
				</positions>
				<commonCountingTime unit="seconds">74.715</commonCountingTime>
				<intensities unit="counts">897 858 892 928 821 796 828 837 848 815 843 835 830 888 887 828 841 867 863 901 809 904 887 857 862 787 849 889 908 853 861 848 871 897 844 869 844 872 846 899 912 851 886 863 901 831 871 865 800 837 865 812 847 867 924 903 828 800 883 870 890 933 886 933 911 872 917 882 832 858 874 883 872 904 974 925 976 1042 1207 1283 1406 1865 2362 2926 3856 4152 3517 3052 2908 2650 1931 1656 1316 1131 1019 1068 955 931 901 904 929 843 851 891 843 884 877 841 906 881 875 825 798 902 857 847 834 827 850 942 836 838 931 849 868 852 821 888 860 821 848 823 826 859 805 847 797 846 825 818 825 800 797 876 857 808 841 833 825 892 873 812 869 826 864 845 894 841 825 834 812 875 855 802 836 785 838 779 750 846 817 846 821 836 814 798 899 847 803 802 824 828 838 838 871 853 805 802 827 818 780 802 845 862 871 867 941 835 831 827 880 833 841 835 827 811 820 802 844 802 839 720 868 874 815 833 864 800 809 830 784 763 819 830 827 816 781 805 819 800 804 838 818 760 786 786 833 808 865 785 835 853 807 789 822 837 893 817 811 822 801 830 896 856 856 819 789 846 881 863 903 805 884 840 869 867 847 817 810 844 879 901 870 872 864 843 891 775 803 805 867 892 842 857 887 896 814 878 916 857 872 886 827 821 875 887 857 817 932 865 888 921 895 951 898 902 931 927 1000 989 1125 1192 1314 1368 1575 1833 2414 2952 3954 5105 6368 6512 5557 4829 4594 4277 3560 2748 2054 1644 1456 1205 1157 1056 985 1026 946 888 895 839 902 896 850 883 829 906 829 834 928 893 853 872 847 859 830 849 838 901 814 908 858 845 772 858 849 770 856 822 822 824 803 869 803 822 860 840 788 881 841 863 786 836 819 856 801 811 853 804 894 811 819 782 819 826 907 851 815 848 834 844 794 841 922 894 838 828 783 867 821 849 797 822 812 850 831 813 859 799 824 802 817 689 761 820 824 764 838 829 842 826 838 803 795 773 833 782 821 827 832 847 862 822 770 785 837 807 799 837 824 836 865 846 865 786 830 887 843</intensities>
			</dataPoints>
			<nonAmbientPoints type="Temperature" unit="K">
				<measurementTimes unit="seconds" deltaTime="1">0 3 4 33 34 64 65 94 95 123 124 153 154 183</measurementTimes>
				<nonAmbientValues>715 715 716 716 717 717 718 718 719 719 720 720 721 721</nonAmbientValues>
			</nonAmbientPoints>
		</scan>
		<scan appendNumber="0" mode="Continuous" scanAxis="Gonio" status="Completed">
			<header>
				<startTimeStamp>2016-12-06T15:01:05-05:00</startTimeStamp>
				<endTimeStamp>2016-12-06T15:04:09-05:00</endTimeStamp>
				<author>
					<name>NCSU-XRD</name>
				</author>
				<source>
					<applicationSoftware version="4.2">Data Collector</applicationSoftware>
					<instrumentControlSoftware version="7.6  20140701">EMPYREAN</instrumentControlSoftware>
					<instrumentID>0000000011140639</instrumentID>
				</source>
			</header>
			<dataPoints>
				<positions axis="2Theta" unit="deg">
					<startPosition>36.01203028</startPosition>
					<endPosition>47.98684793</endPosition>
				</positions>
				<positions axis="Omega" unit="deg">
					<startPosition>18.00601514</startPosition>
					<endPosition>23.99342397</endPosition>
				</positions>
				<positions axis="Z" unit="mm">
					<commonPosition>7.161</commonPosition>
				</positions>
				<commonCountingTime unit="seconds">74.715</commonCountingTime>
				<intensities unit="counts">873 866 859 847 842 863 854 807 864 836 862 826 785 868 851 830 837 846 819 899 839 875 854 902 900 853 901 822 809 816 829 913 846 871 920 842 918 881 852 887 915 812 912 898 815 890 924 851 908 853 850 930 817 858 862 818 895 942 914 836 853 860 877 847 845 842 816 857 922 854 876 874 943 884 957 932 956 989 1059 1316 1440 1829 2324 2832 3839 4005 3518 3056 2888 2574 2055 1530 1304 1228 1049 1049 941 941 925 911 884 908 869 874 845 867 895 878 831 814 887 880 886 864 866 809 846 822 883 786 814 851 807 866 809 785 805 822 869 823 872 881 780 872 854 829 811 855 817 817 780 823 835 801 871 835 766 825 885 870 855 879 873 879 849 887 843 817 795 899 797 865 813 807 826 869 815 869 772 815 851 833 784 855 840 836 888 760 795 831 824 862 865 819 848 818 817 830 803 864 779 791 830 815 777 749 775 784 798 839 811 812 773 817 806 834 824 815 821 828 809 759 825 819 794 798 784 800 806 855 872 891 762 811 826 863 772 836 886 826 883 799 863 857 827 802 849 835 806 854 810 821 705 797 861 793 820 834 830 797 790 819 783 818 822 828 828 824 828 805 862 824 854 858 827 824 886 843 827 875 857 886 813 894 867 772 827 810 849 817 836 874 826 850 839 829 865 809 865 823 887 901 822 924 873 849 879 872 875 853 858 875 863 894 983 917 978 967 1012 993 1126 1231 1251 1396 1589 1862 2295 2927 3855 5165 6384 6662 5505 4730 4507 4352 3526 2720 2014 1652 1447 1222 1156 1064 982 1017 974 976 969 909 893 873 865 880 853 820 849 853 872 861 872 873 834 811 866 869 824 851 807 847 827 848 827 852 853 778 843 880 840 800 790 834 813 829 850 828 880 833 861 798 828 793 860 792 839 766 846 780 855 833 809 809 761 844 757 841 812 842 778 835 837 817 895 784 823 788 836 850 792 797 802 781 796 816 793 850 748 864 842 850 860 778 786 866 815 840 782 833 818 822 837 781 792 728 818 834 862 855 715 752 846 804 842 754 804 851 876 888 834 828 827 783 830 869 801 790 841</intensities>
			</dataPoints>
			<nonAmbientPoints type="Temperature" unit="K">
				<measurementTimes unit="seconds" deltaTime="1">0 91 92 182</measurementTimes>
				<nonAmbientValues>722 722 723 723</nonAmbientValues>
			</nonAmbientPoints>
		</scan>
		<scan appendNumber="0" mode="Continuous" scanAxis="Gonio" status="Completed">
			<header>
				<startTimeStamp>2016-12-06T15:04:15-05:00</startTimeStamp>
				<endTimeStamp>2016-12-06T15:07:19-05:00</endTimeStamp>
				<author>
					<name>NCSU-XRD</name>
				</author>
				<source>
					<applicationSoftware version="4.2">Data Collector</applicationSoftware>
					<instrumentControlSoftware version="7.6  20140701">EMPYREAN</instrumentControlSoftware>
					<instrumentID>0000000011140639</instrumentID>
				</source>
			</header>
			<dataPoints>
				<positions axis="2Theta" unit="deg">
					<startPosition>36.01203028</startPosition>
					<endPosition>47.98684793</endPosition>
				</positions>
				<positions axis="Omega" unit="deg">
					<startPosition>18.00601514</startPosition>
					<endPosition>23.99342397</endPosition>
				</positions>
				<positions axis="Z" unit="mm">
					<commonPosition>7.161</commonPosition>
				</positions>
				<commonCountingTime unit="seconds">74.715</commonCountingTime>
				<intensities unit="counts">830 885 863 833 810 868 839 886 820 914 902 869 838 847 863 900 834 858 823 815 887 876 831 935 881 831 808 847 865 879 913 846 830 865 794 861 912 858 843 885 810 859 904 844 869 937 859 946 871 840 874 857 882 818 888 891 848 889 883 897 846 879 862 912 889 897 859 872 957 842 843 845 880 925 954 953 1023 1098 1142 1277 1514 1726 2293 2990 3843 4103 3526 3094 2928 2758 2039 1609 1365 1224 1085 1016 956 949 924 939 870 832 842 866 894 816 804 897 869 882 829 846 843 887 852 852 854 818 844 804 881 822 823 838 781 916 857 875 904 852 806 927 911 854 863 800 868 829 803 861 836 748 899 907 878 853 863 835 831 819 904 825 891 884 876 826 854 834 832 816 746 832 895 825 807 882 787 811 911 827 826 861 899 825 801 843 813 831 835 883 818 841 795 833 828 821 879 746 813 797 824 861 843 852 854 787 887 878 790 830 851 797 816 735 836 878 834 819 857 833 824 820 829 823 852 769 860 845 794 907 826 830 784 789 845 787 838 835 857 812 797 882 811 767 825 814 764 823 846 808 827 811 814 824 861 850 815 807 851 797 806 794 849 796 789 776 817 829 833 819 852 861 865 860 801 848 820 845 887 815 840 884 880 872 839 812 818 874 828 824 850 824 892 892 790 872 841 930 834 775 849 874 841 831 872 856 864 854 953 885 869 924 930 911 896 926 988 964 989 1063 1085 1203 1255 1520 1659 1829 2349 3029 3903 5191 6361 6396 5609 4868 4511 4281 3531 2634 2012 1638 1433 1266 1151 1077 1011 959 945 944 901 856 873 905 825 876 870 884 880 860 859 837 875 901 844 810 823 866 846 797 765 827 891 826 829 838 839 821 821 838 878 787 803 895 799 800 756 837 804 771 854 869 865 818 807 818 857 884 872 831 843 840 808 833 781 842 856 797 827 832 807 808 820 845 842 827 808 783 808 861 802 869 767 818 794 861 861 852 847 836 799 865 801 812 788 816 843 818 856 828 815 782 799 800 868 823 795 808 808 830 817 809 809 826 821 819 782 821 828 822 779 822 813 827 815 839 874 812 851</intensities>
			</dataPoints>
			<nonAmbientPoints type="Temperature" unit="K">
				<measurementTimes unit="seconds" deltaTime="1">0 183</measurementTimes>
				<nonAmbientValues>723 723</nonAmbientValues>
			</nonAmbientPoints>
		</scan>
	</xrdMeasurement>
</xrdMeasurements>